<mujoco>
  <option timestep="0.001"/>

  <visual>
    <headlight diffuse="0.6 0.6 0.6" ambient="0.3 0.3 0.3" specular="0 0 0" />
    <rgba haze="0.15 0.25 0.35 1" />
    <global azimuth="160" elevation="-20" />
  </visual>

  <asset>
    <texture type="skybox" builtin="gradient" rgb1="0.3 0.5 0.7" rgb2="0 0 0" width="512" height="3072" />
    <texture type="2d" name="groundplane" builtin="checker" mark="edge" rgb1="0.2 0.3 0.4" rgb2="0.1 0.2 0.3" markrgb="0.8 0.8 0.8" width="300" height="300" />
    <material name="groundplane" texture="groundplane" texuniform="true" texrepeat="5 5" reflectance="0.2" />
  </asset>

  <default>
    <joint type="hinge" axis="0 -1 0" frictionloss="0.001" armature="0.005" />
    <geom type="cylinder" size="0.02" />
    <default class="visual">
      <geom density="0" contype="0" conaffinity="0" group="1" />
    </default>
    <default class="collision">
      <geom density="2700" contype="2" conaffinity="2" rgba="0.5 0.5 0.5 0.3" group="2" />
    </default>
  </default>


  <worldbody>
    <light pos="0 0 3.5" dir="0 0 -1" directional="true" />
    <geom name="floor" size="0 0 0.05" contype="2" conaffinity="2" pos="0 0 0" type="plane" material="groundplane" />
    <camera name="fixed" pos="0 -1 0" xyaxes="1 0 0 0 0 1" />

     <body name="toplink" pos="0 0 .3">
        <joint name="root" type="free"/>
        <geom name="toplink_visual" class="visual" fromto="0 0 0 0 0 -0.23" rgba="1 0.3 0.3 1"/>
        <geom name="toplink_collision" class="collision" fromto="0 0 0 0 0 -.20"/>
      
      <body name="bottomlink" pos="0 0 -.25" quat="0 0.7071068 0 0.7071068">
        <joint name="actjoint" type="hinge" axis="0 -1 0" frictionloss="0.001" armature="0.005"/>
        <geom name="bottomlink_visual" class="visual" fromto="0 0 0 0 0 -.2" rgba="1 1 1 1"/>
        <geom name="bottomlink_collision" class="collision" fromto="0 0 0 0 0 -.2"/>
        <site name="force_site" pos="0.0 0.0 0.0" size="0.01"/>
      </body>

    </body>
  </worldbody>


  <contact>
    <pair geom1="toplink_collision" geom2="bottomlink_collision"/>
  </contact>

  <sensor>
    <force name="force_sensor" site="force_site" />
  </sensor>

  <actuator>
    <motor name="rs04joint" joint="actjoint"/>
  </actuator>
</mujoco>
